Workbook

Sheet 凡例・サマリー
B2: 単体テスト カバレッジ・マトリクス
B3: 調査対象: RIManager Impl (printer-fw) / 作成日: 2026-08-27
B4: 調査範囲: core/ 配下の全public method・products/common/rim_api.cpp・products/printer_a/printer_a.cpp のC-API群。test/unit/ 配下の既存テストとの突合による、正常系・異常系の網羅状況の可視化。
B6: ■ 凡例
B7: ⭕ | C7: 直接テストが存在する（対象メソッドを名指しで検証）
B8: △ | C8: 間接的/部分的にのみテストされている（他メソッド経由・一部分岐のみ等）
B9: ❌ | C9: テストが存在しない
B10: ー | C10: 対象外（純粋なデータ構造/インターフェース宣言のみ等でロジックがない）
B12: ■ シート構成
B13: カバレッジ一覧 | C13: レイヤ/クラス/メソッド単位の一覧表。正常系・異常系のテスト有無と、想定される異常系シナリオを記載。
B14: 調査メモ・注意事項 | C14: 調査中に見つかった設計上の疑問点（重複クラス、未実装/デッドコード、初期値の扱い等）。
B17: ■ サマリー（調査グループ別）
B18: 調査グループ | C18: 対象メソッド数 | D18: 正常系⭕ | E18: 正常系△ | F18: 正常系❌ | G18: 正常系ー | H18: 異常系⭕ | I18: 異常系△ | J18: 異常系❌ | K18: 異常系ー
B19: A: Adapter/Product/Store/C-API | C19: =COUNTIF(カバレッジ一覧!$I:$I,$M19) -> 98 | D19: =COUNTIFS(カバレッジ一覧!$I:$I,$M19,カバレッジ一覧!$D:$D,"⭕") -> 42 | E19: =COUNTIFS(カバレッジ一覧!$I:$I,$M19,カバレッジ一覧!$D:$D,"△") -> 10 | F19: =COUNTIFS(カバレッジ一覧!$I:$I,$M19,カバレッジ一覧!$D:$D,"❌") -> 43 | G19: =COUNTIFS(カバレッジ一覧!$I:$I,$M19,カバレッジ一覧!$D:$D,"ー") -> 3 | H19: =COUNTIFS(カバレッジ一覧!$I:$I,$M19,カバレッジ一覧!$F:$F,"⭕") -> 12 | I19: =COUNTIFS(カバレッジ一覧!$I:$I,$M19,カバレッジ一覧!$F:$F,"△") -> 0 | J19: =COUNTIFS(カバレッジ一覧!$I:$I,$M19,カバレッジ一覧!$F:$F,"❌") -> 83 | K19: =COUNTIFS(カバレッジ一覧!$I:$I,$M19,カバレッジ一覧!$F:$F,"ー") -> 3 | M19: Adapter/Product/Store/C-API
B20: B: Storage/Accessor/Snapshot | C20: =COUNTIF(カバレッジ一覧!$I:$I,$M20) -> 44 | D20: =COUNTIFS(カバレッジ一覧!$I:$I,$M20,カバレッジ一覧!$D:$D,"⭕") -> 20 | E20: =COUNTIFS(カバレッジ一覧!$I:$I,$M20,カバレッジ一覧!$D:$D,"△") -> 6 | F20: =COUNTIFS(カバレッジ一覧!$I:$I,$M20,カバレッジ一覧!$D:$D,"❌") -> 17 | G20: =COUNTIFS(カバレッジ一覧!$I:$I,$M20,カバレッジ一覧!$D:$D,"ー") -> 1 | H20: =COUNTIFS(カバレッジ一覧!$I:$I,$M20,カバレッジ一覧!$F:$F,"⭕") -> 12 | I20: =COUNTIFS(カバレッジ一覧!$I:$I,$M20,カバレッジ一覧!$F:$F,"△") -> 1 | J20: =COUNTIFS(カバレッジ一覧!$I:$I,$M20,カバレッジ一覧!$F:$F,"❌") -> 30 | K20: =COUNTIFS(カバレッジ一覧!$I:$I,$M20,カバレッジ一覧!$F:$F,"ー") -> 1 | M20: Storage/Accessor/Snapshot
B21: C: Capability | C21: =COUNTIF(カバレッジ一覧!$I:$I,$M21) -> 31 | D21: =COUNTIFS(カバレッジ一覧!$I:$I,$M21,カバレッジ一覧!$D:$D,"⭕") -> 10 | E21: =COUNTIFS(カバレッジ一覧!$I:$I,$M21,カバレッジ一覧!$D:$D,"△") -> 11 | F21: =COUNTIFS(カバレッジ一覧!$I:$I,$M21,カバレッジ一覧!$D:$D,"❌") -> 6 | G21: =COUNTIFS(カバレッジ一覧!$I:$I,$M21,カバレッジ一覧!$D:$D,"ー") -> 4 | H21: =COUNTIFS(カバレッジ一覧!$I:$I,$M21,カバレッジ一覧!$F:$F,"⭕") -> 9 | I21: =COUNTIFS(カバレッジ一覧!$I:$I,$M21,カバレッジ一覧!$F:$F,"△") -> 2 | J21: =COUNTIFS(カバレッジ一覧!$I:$I,$M21,カバレッジ一覧!$F:$F,"❌") -> 16 | K21: =COUNTIFS(カバレッジ一覧!$I:$I,$M21,カバレッジ一覧!$F:$F,"ー") -> 4 | M21: Capability
B22: D: Publisher | C22: =COUNTIF(カバレッジ一覧!$I:$I,$M22) -> 50 | D22: =COUNTIFS(カバレッジ一覧!$I:$I,$M22,カバレッジ一覧!$D:$D,"⭕") -> 33 | E22: =COUNTIFS(カバレッジ一覧!$I:$I,$M22,カバレッジ一覧!$D:$D,"△") -> 4 | F22: =COUNTIFS(カバレッジ一覧!$I:$I,$M22,カバレッジ一覧!$D:$D,"❌") -> 5 | G22: =COUNTIFS(カバレッジ一覧!$I:$I,$M22,カバレッジ一覧!$D:$D,"ー") -> 8 | H22: =COUNTIFS(カバレッジ一覧!$I:$I,$M22,カバレッジ一覧!$F:$F,"⭕") -> 14 | I22: =COUNTIFS(カバレッジ一覧!$I:$I,$M22,カバレッジ一覧!$F:$F,"△") -> 2 | J22: =COUNTIFS(カバレッジ一覧!$I:$I,$M22,カバレッジ一覧!$F:$F,"❌") -> 26 | K22: =COUNTIFS(カバレッジ一覧!$I:$I,$M22,カバレッジ一覧!$F:$F,"ー") -> 8 | M22: Publisher
B23: 合計 | C23: =SUM(C19:C22) -> 223 | D23: =SUM(D19:D22) -> 105 | E23: =SUM(E19:E22) -> 31 | F23: =SUM(F19:F22) -> 71 | G23: =SUM(G19:G22) -> 16 | H23: =SUM(H19:H22) -> 47 | I23: =SUM(I19:I22) -> 5 | J23: =SUM(J19:J22) -> 155 | K23: =SUM(K19:K22) -> 16

Sheet カバレッジ一覧
A1: レイヤ | B1: クラス | C1: メソッド | D1: 正常系 | E1: 正常系テスト（根拠） | F1: 異常系 | G1: 実施済み異常系シナリオ | H1: 想定される異常系シナリオ（提案） | I1: 調査グループ
A2: Adapter | B2: AdapterDispatcher | C2: bool Dispatch(const RIMDataItem&) | D2: ⭕ | E2: AdapterDispatcherTest.DispatchNormalizesAndPushesToRouteQueue; AdapterDispatcherTest.DispatchStoresNormalizedValueWithDefinitionSetValueType | F2: ⭕ | G2: AdapterDispatcherTest.DispatchRejectsUnregisteredDataId (unknown data id → FindDataItem returns nullptr); AdapterDispatcherTest.DispatchRejectsRawValueTypeMismatch (item.value.type != rawValueType) | H2: Data item found in context but missing from RouteProvider's routing table (queue==nullptr path, line `if (queue == nullptr) return false;`) — distinct from "unregistered in context"; normalize() returning a RIMValue whose type doesn't match definition->setValueType (silently mismatched, not validated); queue->storeQueue->Push() returning false (e.g. after Shutdown) is ignored — Dispatch() always returns true in that branch regardless of Push's result, a real bug worth a regression test | I2: Adapter/Product/Store/C-API
A3: Product/Definition | B3: ProductDefinition.cpp (free fn) | C3: const DomainDefinition* FindDomain(product, string_view name) | D3: ⭕ | E3: ProductDefinitionLookupTest.FindExistingDomain | F3: ❌ | H3: Name not found (empty product.domains); domainCount==0 with domains==nullptr; case-sensitivity of name compare | I3: Adapter/Product/Store/C-API
A4: Product/Definition | B4: ProductDefinition.cpp (free fn) | C4: const RouteDefinition* FindRoute(product, string_view name) | D4: ⭕ | E4: ProductDefinitionTest.RouteHasCompressionPolicy; ProductDefinitionTest.RouteHasMinimumNotifyInterval | F4: ❌ | H4: Name not found; routeCount==0 | I4: Adapter/Product/Store/C-API
A5: Product/Definition | B5: ProductDefinition.cpp (free fn) | C5: const RouteDefinition* FindRoute(product, uint32_t id) | D5: ❌ | E5: — (only ProductContext::FindRoute(id) tested via map, not this linear-scan free fn directly) | F5: ❌ | H5: Unknown id; routeCount==0; routes==nullptr | I5: Adapter/Product/Store/C-API
A6: Product/Definition | B6: ProductDefinition.cpp (free fn) | C6: const DataItemDefinition* FindDataItem(product, string_view name) | D6: ⭕ | E6: ProductDefinitionLookupTest.FindExistingDataItem | F6: ❌ | H6: Name not found; empty dataItems array | I6: Adapter/Product/Store/C-API
A7: Product/Definition | B7: ProductDefinition.cpp (free fn) | C7: const DataItemDefinition* FindDataItem(product, RIDataId id) | D7: ⭕ | E7: ProductDefinitionLookupTest.FindErrorList (also used internally in ValidateProductDefinition tests) | F7: ❌ | H7: Unknown id (as free fn, not via ProductContext's O(1) map path — different code path than ProductContextTest.UnknownDataReturnsNull) | I7: Adapter/Product/Store/C-API
A8: Product/Definition | B8: ProductDefinition.cpp (free fn) | C8: const CapabilityItemDefinition* FindCapability(product, string_view name) | D8: ⭕ | E8: ProductDefinitionLookupTest.FindExistingCapability | F8: ❌ | H8: Name not found | I8: Adapter/Product/Store/C-API
A9: Product/Definition | B9: ProductDefinition.cpp (free fn) | C9: const CapabilityItemDefinition* FindCapability(product, RICapabilityId id) | D9: ⭕ | E9: ProductDefinitionLookupTest.FindCapabilityById | F9: ❌ | H9: Unknown id; capabilityCount==0 | I9: Adapter/Product/Store/C-API
A10: Product/Definition | B10: ProductDefinition.cpp (free fn) | C10: const FacadeItemDefinition* FindFacade(product, string_view name) | D10: ❌ | E10: Not exercised by any assigned test file (facade tests live in test/unit/capability/FacadeManagerTest.cpp — out of this group's scope) | F10: ❌ | H10: Not-found name; empty facades array; note this is the renamed "FindPipeline" the task spec expected | I10: Adapter/Product/Store/C-API
A11: Product/Definition | B11: ProductDefinition.cpp (free fn) | C11: const FacadeItemDefinition* FindFacade(product, RIFacadeId id) | D11: ❌ | E11: Same as above | F11: ❌ | H11: Unknown id | I11: Adapter/Product/Store/C-API
A12: Product/Definition | B12: ProductDefinition.cpp (free fn) | C12: const RouteDefinition* GetRoutes(product) | D12: ❌ | E12: Not directly asserted in assigned files; only used internally by ProductContext ctor and RouteProvider::Initialize | F12: ❌ | H12: product.routes==nullptr with routeCount>0 (mismatch); routeCount==0 returning valid-but-unused pointer | I12: Adapter/Product/Store/C-API
A13: Product/Definition | B13: ProductDefinition.cpp (free fn) | C13: size_t GetRouteCount(product) | D13: ❌ | E13: Not directly asserted | F13: ❌ | H13: — | I13: Adapter/Product/Store/C-API
A14: Product/Definition | B14: ProductDefinition.cpp (free fn) | C14: const CapabilityItemDefinition* GetCapabilities(product) | D14: ⭕ | E14: ProductDefinitionLookupTest.EnumerateCapabilities (checks non-null + count>0) | F14: ❌ | H14: capabilityCount==0 / nullptr pointer combination | I14: Adapter/Product/Store/C-API
... A21: Product/Definition | B21: ProductDefinition.cpp (free fn) | C21: size_t GetDomainCount(product) | D21: ⭕ | E21: ProductDefinitionLookupTest.EnumerateDomains | F21: ❌ | H21: — | I21: Adapter/Product/Store/C-API
A22: Product/Definition | B22: ProductDefinition.cpp (free fn) | C22: bool ValidateProductDefinition(product) | D22: ⭕ | E22: ProductDefinitionTest.PrinterAProductDefinitionIsValid | F22: ⭕ | G22: ProductDefinitionTest.RejectDuplicateDomain (dup domain name); RejectDuplicateCapability (dup capability *name*, despite test's title suggesting id); RejectDuplicateDataItemName; RejectDuplicateDataItemId; RejectDuplicateCapabilityId; RejectDataItemWithUnknownRoute (dataItem.routeId not in routes) | H22: DataItem.domain pointer whose name isn't present in product.domains (the `if (!FindDomain(...)) return false;` branch — currently untested); DataItem.domain==nullptr (explicit early-return branch, untested); Capability.requiredDataIds referencing an unknown DataId (untested); Facade duplicate name; Facade duplicate id; Facade.requiredCapabilityIds referencing unknown capability id — none of the Facade-validation branches have any test coverage at all | I22: Adapter/Product/Store/C-API
A23: Product/ProductContext | B23: ProductContext | C23: ProductContext(const ProductDefinition&) [ctor] | D23: △ | E23: Exercised as fixture setup in ProductContextTest, RouteResolverTest, AdapterDispatcherTest, DataStoreWorkerTest, RouteExecutorTest — but never directly asserted on its own | F23: ❌ | H23: Construct with a fully empty ProductDefinition (all nullptr/0) — verify no crash and GetDataItems()==nullptr; construct with duplicate DataItem/Capability ids (constructor doesn't call ValidateProductDefinition, so unordered_map::emplace silently keeps the first and drops the duplicate — currently unverified/undocumented behavior) | I23: Adapter/Product/Store/C-API
A24: Product/ProductContext | B24: ProductContext | C24: const DataDomainMap& DataDomains() const | D24: ❌ | E24: Not asserted in assigned files | F24: ❌ | H24: — | I24: Adapter/Product/Store/C-API
A25: Product/ProductContext | B25: ProductContext | C25: const CapabilityRequiredDomainMap& CapabilityDomains() const | D25: ❌ | E25: Not asserted in assigned files | F25: ❌ | H25: — | I25: Adapter/Product/Store/C-API
A26: Product/ProductContext | B26: ProductContext | C26: const FacadeRequiredCapabilityMap& FacadeCapabilities() const | D26: ❌ | E26: Not asserted in assigned files | F26: ❌ | H26: — | I26: Adapter/Product/Store/C-API
A27: Product/ProductContext | B27: ProductContext | C27: const CapabilityDependencyMap& CapabilityDependencies() const | D27: ❌ | E27: Not asserted in assigned files | F27: ❌ | H27: — | I27: Adapter/Product/Store/C-API
A28: Product/ProductContext | B28: ProductContext | C28: const FacadeDependencyMap& FacadeDependencies() const | D28: ❌ | E28: Not asserted in assigned files | F28: ❌ | H28: — | I28: Adapter/Product/Store/C-API
A29: Product/ProductContext | B29: ProductContext | C29: const DataItemDefinition* FindDataItem(RIDataId) const | D29: ⭕ | E29: ProductContextTest.FindDataItemById; ProductContextTest.RepeatedLookupReturnsSamePointer | F29: ⭕ | G29: ProductContextTest.UnknownDataReturnsNull (id=0xFFFFFFFF not found → nullptr) | H29: Also used pervasively as a dependency of AdapterDispatcher::Dispatch and DataStoreWorker::Process — already covered by those callers' own not-found tests | I29: Adapter/Product/Store/C-API
A30: Product/ProductContext | B30: ProductContext | C30: std::vector<string_view> GetDomains() const | D30: ❌ | E30: Not directly asserted (constructor uses it internally) | F30: ❌ | H30: Empty domains_ returns empty vector — untested | I30: Adapter/Product/Store/C-API
A31: Product/ProductContext | B31: ProductContext | C31: const RouteDefinition* GetRoutes() const | D31: ❌ | E31: Not directly asserted; used internally by RouteProvider::Initialize | F31: ❌ | H31: routes_.empty() → returns nullptr (explicit ternary branch) — untested | I31: Adapter/Product/Store/C-API
A32: Product/ProductContext | B32: ProductContext | C32: size_t GetRouteCount() const | D32: ⭕ | E32: RouteExecutorTest.RouteProviderCreatesQueueForEveryRouteDefinition (compares to routeProvider.GetQueues().size()) | F32: ❌ | H32: — | I32: Adapter/Product/Store/C-API
A33: Product/ProductContext | B33: ProductContext | C33: const DataItemDefinition* GetDataItems() const | D33: ❌ | E33: Not directly asserted; used internally by RouteProvider::Initialize | F33: ❌ | H33: dataItems_.empty() → nullptr branch — untested | I33: Adapter/Product/Store/C-API
A34: Product/ProductContext | B34: ProductContext | C34: size_t GetDataItemCount() const | D34: ❌ | E34: Not directly asserted | F34: ❌ | H34: — | I34: Adapter/Product/Store/C-API
A35: Product/ProductContext | B35: ProductContext | C35: const CapabilityItemDefinition* GetCapabilities() const | D35: ❌ | E35: Not directly asserted (capability tests out of scope) | F35: ❌ | H35: capabilities_.empty() → nullptr branch | I35: Adapter/Product/Store/C-API
A36: Product/ProductContext | B36: ProductContext | C36: size_t GetCapabilityCount() const | D36: ❌ | E36: Not directly asserted | F36: ❌ | H36: — | I36: Adapter/Product/Store/C-API
A37: Product/ProductContext | B37: ProductContext | C37: const CapabilityItemDefinition* FindCapability(RICapabilityId) const | D37: ⭕ | E37: ProductContextTest.FindCapabilityById | F37: ❌ | H37: Unknown capability id → nullptr (parallel test to FindDataItem's UnknownDataReturnsNull doesn't exist for this method) | I37: Adapter/Product/Store/C-API
A38: Product/ProductContext | B38: ProductContext | C38: DomainId FindDataDomainId(RIDataId) const | D38: △ | E38: Used/asserted in DataStoreWorkerTest.UpdatePartitionStorage / StoreErrorList / RouteExecutorTest.ProcessItemFromRouteQueue (asserts result != kInvalidDomainId) | F38: ❌ | H38: Unknown/unmapped data id → kInvalidDomainId return path is never explicitly exercised with an assertion that this happens (DataStoreWorker::Process silently drops such items — no test proves that drop-on-invalid-domain behavior) | I38: Adapter/Product/Store/C-API
A39: Product/ProductContext | B39: ProductContext | C39: DomainId FindCapabilityDomainId(RICapabilityId) const | D39: ❌ | E39: Not tested in assigned files (only in capability/ layer tests, out of scope) | F39: ❌ | H39: Unknown capability id → kInvalidDomainId | I39: Adapter/Product/Store/C-API
A40: Product/ProductContext | B40: ProductContext | C40: const FacadeItemDefinition* FindFacade(RIFacadeId) const | D40: ❌ | E40: Not tested in assigned files | F40: ❌ | H40: Unknown facade id → nullptr | I40: Adapter/Product/Store/C-API
A41: Product/ProductContext | B41: ProductContext | C41: DomainId FindFacadeDomainId(RIFacadeId) const | D41: ❌ | E41: Not tested in assigned files | F41: ❌ | H41: Unknown facade id → kInvalidDomainId | I41: Adapter/Product/Store/C-API
... A44: Product/RouteProvider | B44: RouteProvider | C44: void Initialize(const ProductContext&) | D44: ⭕ | E44: AdapterDispatcherFixture ctor (AdapterDispatcherTest.*); RouteExecutorTest.RouteProviderCreatesQueueForEveryRouteDefinition | F44: ❌ | H44: Re-calling Initialize() a second time on the same instance (queues_.clear()/routingTable_.clear() then rebuild) — dangling `RouteQueues*` risk for anyone holding a pointer from before; DataItemDefinition.routeId referencing a route that doesn't exist triggers `assert(route != nullptr)` — crashes in debug builds, untested; empty ProductDefinition (routeCount==0, dataItemCount==0) | I44: Adapter/Product/Store/C-API
A45: Product/RouteProvider | B45: RouteProvider | C45: RouteQueues* Find(RIDataId) const | D45: ⭕ | E45: AdapterDispatcherTest.DispatchNormalizesAndPushesToRouteQueue (found path); RouteExecutorTest.ProcessItemFromRouteQueue (via GetQueues().find) | F45: ⭕ | G45: AdapterDispatcherTest.DispatchRejectsUnregisteredDataId (explicitly asserts Find(unregisteredId) == nullptr) | H45: Call Find() before Initialize() has ever run (empty routingTable_) | I45: Adapter/Product/Store/C-API
A46: Product/RouteProvider | B46: RouteProvider | C46: const auto& GetQueues() const | D46: ⭕ | E46: RouteExecutorTest.* (iterates/looks up "ValueRoute"); RIM_api Initialize-style usage in rim_api.cpp | F46: ❌ | H46: — (trivial getter) | I46: Adapter/Product/Store/C-API
A47: Product/RouteExecutor | B47: RouteExecutor | C47: RouteExecutor(ctx, queues, domainStore, capabilityManager, facadeManager, publisherQueue, capSnapshotProvider, facadeSnapshotProvider) | D47: ⭕ | E47: RouteExecutorTest.RouteExecutorCountMatchesRouteCount; RouteExecutorTest.ProcessItemFromRouteQueue | F47: ❌ | H47: Construct with a RouteQueues whose storeQueue/capabilityQueue unique_ptrs are null (e.g. from QueueFactory::Create returning {} for an unhandled QueuePolicy) — dereferenced immediately in DataStoreWorker/CapabilityWorker ctors, likely UB/crash, untested | I47: Adapter/Product/Store/C-API
A48: Product/RouteExecutor | B48: RouteExecutor | C48: ~RouteExecutor() | D48: ❌ | E48: Only exercised implicitly at scope-exit of test fixtures; no explicit destruction-behavior assertion | F48: ❌ | H48: Verify destructor safely calls Stop() when Start() was never called; verify no double-join crash | I48: Adapter/Product/Store/C-API
...

Sheet 調査メモ・注意事項
B2: 調査中に見つかった設計上の注意点・疑問点
B4: [A] | C4: AdapterDispatcher::Dispatch は queue->storeQueue->Push() の戻り値を確認しておらず、Push が false（Shutdown後等）を返しても常に true を返す。回帰テストが望ましい。
B5: [A] | C5: RIM_GetNotification には他のAPIと違い !g_context のガードが一切ない。RIM_Create() 前に呼ぶと g_context の null unique_ptr を参照しクラッシュする可能性が高い（要優先対応）。
B6: [A] | C6: RIMValueFactory::CreateInt64 / CreateUInt64 / CreateString は現行コードから一切呼び出されておらず、テストも皆無。
B7: [A] | C7: RIMValueFactory::CreateBinaryInput は現行ツリーには存在しない（old_0818/old_0820 のみに残存）。
B8: [A] | C8: core/store/include/StoreFunctions.hpp・DiffFunctions.hpp はどの製品定義からも#includeされていないデッドコード。DiffFunctions.hpp の DefaultDiff は RIMValue 全体を memcmp しており、kBinary/kString のようなポインタ保持型には本質的に安全でない。
B9: [A] | C9: RouteProvider::Initialize は再実行するとキューを作り直すため、以前の Find() 結果（RouteQueues*）を保持しているコードがあればダングリングポインタになる。また route 未解決時は assert に依存しており、Release ビルドでは検出されない。
B10: [B] | C10: core/storage/include/SnapshotBuilder.hpp と core/storage/snapshot/include/SnapshotBuilder.hpp が同一クラスを重複宣言している（内容は一致しているため実害はないが、インクルードパスの順序に依存する設計になっている）。
B11: [B] | C11: 旧 DomainStorage / DomainStorageRegistry は現行ツリーでは PartitionStorage / PartitionStorageRegistry にリネームされている。
B12: [B] | C12: test/unit/accessor/ReactiveInfoManagerTest.cpp という名前だが、実際には ReactiveInfoManager というクラスは存在せず、SubscriberMailboxManager と NotificationReceiver（Publisherレイヤ）をテストしている。テストファイル名が実体と乖離している。
B13: [B] | C13: RIMSnapshot::GetBinaryHash() はヘッダで宣言されているが実装(.cpp)がどこにも存在しない。呼び出すとリンクエラーになる可能性が高い。
B14: [B] | C14: FacadeRequiredCapabilityMap はテストが皆無で、コンストラクタ内のドメイン解決ロジックもコメントで「暫定」と明記された未完成の実装。
B15: [B] | C15: FacadeAccessor はテストファイルからの参照が一件もなく、完全に未テスト。
... B20: [D] | C20: 詳細は「カバレッジ一覧」シートのPublisher行を参照。CallbackQueue/SubscriberMailboxManager等のShutdown後Push・並行アクセス系のテストが手薄。
